[2024-09-03T13:00:43.478+0000] {taskinstance.py:1159} INFO - Dependencies all met for dep_context=non-requeueable deps ti=<TaskInstance: run_daily_order_update_dag.run_daily_order_update_task manual__2024-09-03T12:55:40.242077+00:00 [queued]>
[2024-09-03T13:00:43.482+0000] {taskinstance.py:1159} INFO - Dependencies all met for dep_context=requeueable deps ti=<TaskInstance: run_daily_order_update_dag.run_daily_order_update_task manual__2024-09-03T12:55:40.242077+00:00 [queued]>
[2024-09-03T13:00:43.483+0000] {taskinstance.py:1361} INFO - Starting attempt 2 of 2
[2024-09-03T13:00:43.488+0000] {taskinstance.py:1382} INFO - Executing <Task(BashOperator): run_daily_order_update_task> on 2024-09-03 12:55:40.242077+00:00
[2024-09-03T13:00:43.493+0000] {standard_task_runner.py:57} INFO - Started process 254 to run task
[2024-09-03T13:00:43.497+0000] {standard_task_runner.py:84} INFO - Running: ['***', 'tasks', 'run', 'run_daily_order_update_dag', 'run_daily_order_update_task', 'manual__2024-09-03T12:55:40.242077+00:00', '--job-id', '140', '--raw', '--subdir', 'DAGS_FOLDER/run_daily_order_update.py', '--cfg-path', '/tmp/tmp_9nytwf5']
[2024-09-03T13:00:43.500+0000] {standard_task_runner.py:85} INFO - Job 140: Subtask run_daily_order_update_task
[2024-09-03T13:00:43.528+0000] {task_command.py:415} INFO - Running <TaskInstance: run_daily_order_update_dag.run_daily_order_update_task manual__2024-09-03T12:55:40.242077+00:00 [running]> on host 1ff78387476a
[2024-09-03T13:00:43.566+0000] {taskinstance.py:1660} INFO - Exporting env vars: AIRFLOW_CTX_DAG_OWNER='***' AIRFLOW_CTX_DAG_ID='run_daily_order_update_dag' AIRFLOW_CTX_TASK_ID='run_daily_order_update_task' AIRFLOW_CTX_EXECUTION_DATE='2024-09-03T12:55:40.242077+00:00' AIRFLOW_CTX_TRY_NUMBER='2' AIRFLOW_CTX_DAG_RUN_ID='manual__2024-09-03T12:55:40.242077+00:00'
[2024-09-03T13:00:43.568+0000] {subprocess.py:63} INFO - Tmp dir root location: /tmp
[2024-09-03T13:00:43.568+0000] {subprocess.py:75} INFO - Running command: ['/bin/bash', '-c', 'python3 /opt/***/python_scripts/run_daily_order_update.py']
[2024-09-03T13:00:43.576+0000] {subprocess.py:86} INFO - Output:
[2024-09-03T13:00:43.633+0000] {subprocess.py:93} INFO - python3: can't open file '/opt/***/python_scripts/run_daily_order_update.py': [Errno 2] No such file or directory
[2024-09-03T13:00:43.635+0000] {subprocess.py:97} INFO - Command exited with return code 2
[2024-09-03T13:00:43.645+0000] {taskinstance.py:1943} ERROR - Task failed with exception
Traceback (most recent call last):
  File "/home/airflow/.local/lib/python3.8/site-packages/airflow/operators/bash.py", line 210, in execute
    raise AirflowException(
airflow.exceptions.AirflowException: Bash command failed. The command returned a non-zero exit code 2.
[2024-09-03T13:00:43.650+0000] {taskinstance.py:1400} INFO - Marking task as FAILED. dag_id=run_daily_order_update_dag, task_id=run_daily_order_update_task, execution_date=20240903T125540, start_date=20240903T130043, end_date=20240903T130043
[2024-09-03T13:00:43.657+0000] {standard_task_runner.py:104} ERROR - Failed to execute job 140 for task run_daily_order_update_task (Bash command failed. The command returned a non-zero exit code 2.; 254)
[2024-09-03T13:00:43.678+0000] {local_task_job_runner.py:228} INFO - Task exited with return code 1
[2024-09-03T13:00:43.688+0000] {taskinstance.py:2784} INFO - 0 downstream tasks scheduled from follow-on schedule check
